Workbook

Sheet Приложение 4
A1: № | B1: Группа | C1: Ед. | D1: Расценка | E1: Что входит
B2: 类别 | C2: 单位 | D2: 单价 | E2: 包含内容
A3: 1 | B3: Технологическое оборудование | C3: т | D3: USD/т | E3: Мельница, сепараторы, фильтры, дымососы, дозаторы, горелки, насосы, компрессоры, элеватор, конвейеры, питатели, затворы, клапаны
B4: 工艺设备 | C4: 吨 | D4: 美元/吨 | E4: 磨机、选粉机、收尘器、引风机、计量器、燃烧器、泵、压缩机、提升机、输送机、给料机、闸板、阀门
A5: 2 | B5: Металлоконструкции | C5: т | D5: USD/т | E5: Этажерки, площадки, лестницы, опоры, рамы, силосы, бункеры, навесы, газоходные опоры, лотки, жёлоба, переходники, защитная обшивка (оцинк. лист)
B6: 金属结构 | C6: 吨 | D6: 美元/吨 | E6: 支架、平台、楼梯、支柱、框架、料仓、料斗、雨棚、烟道支架、托架、溜槽、过渡件、保护外壳（镀锌板）
A7: 3 | B7: Трубопроводы и газоходы | C7: т | D7: USD/т | E7: Технологические трубопроводы, газоходы, углепроводы, воздуховоды, арматура, компенсаторы
B8: 管道与烟道 | C8: 吨 | D8: 美元/吨 | E8: 工艺管道、烟道、输煤管道、风管、管件、补偿器
A9: 4 | B9: Термоизоляция | C9: м² | D9: USD/м³ | E9: Минеральная вата на газоходах/дымососах/фильтрах
B10: 保温隔热 | C10: m² | D10: 美元/m³ | E10: 烟道/引风机/收尘器上的矿棉
A11: 5 | B11: Демонтаж | C11: т | D11: USD/т (пониж.) | E11: Демонтаж существующих горелок, площадок, фахверка
B12: 拆除 | C12: 吨 | D12: 美元/吨（降序） | E12: 拆除现有燃烧器、平台、填充墙框架
A13: 6 | B13: Электромонтаж и КИПиА | C13: к-т | D13: фикс. сумма | E13: Шкафы, кабель, лотки, датчики, газоанализаторы, шиберы (шт), взрывозащита, заземление
B14: 电气安装与自控仪表 | C14: 套 | D14: 固定金额 | E14: 柜体、电缆、桥架、传感器、气体分析仪、闸板（个）、防爆、接地
A15: 7 | B15: Инертизация и пожаротушение | C15: — | D15: фикс. сумма | E15: Опоры, баллоны, короба, трубопроводы азота/инертизации
B16: 惰性化与消防灭火 | D16: 固定金额 | E16: 支架、气瓶、箱体、氮气/惰性化管道
A17: 8 | B17: Ограждающие конструкции | C17: м² | D17: USD/т | E17: Сэндвич-панели, профнастил (стены, кровля)
B18: 围护结构 | C18: m² | D18: 美元/吨 | E18: 夹芯板、压型板（墙体、屋面）
A19: 9 | B19: Железобетонные конструкции | C19: м³ | D19: USD/т | E19: Плиты, отмостка, цоколь, топпинг, двери, окна, ворота
B20: 钢筋混凝土结构 | C20: m³ | D20: 美元/吨 | E20: 楼板、散水、勒脚、面层、门、窗、大门

Sheet Приложение №1
A1: № | B1: Код оборудования | C1: Наименование работы | D1: Зона ответственности | E1: Категория | F1: Объем | H1: Проект | I1: Цена за ед., Дол. США | J1: Сумма
B2: 设备代码 | C2: 工作名称 | D2: 责任区域 | E2: 类别 | F2: 工程量 | H2: 项目 | I2: 单价（美元） | J2: 金额
F3: Ед. изм. | G3: Кол-во
F4: 计量单位 | G4: 数量
A5: 1 | C5: 2 | D5: 3 | E5: 4 | F5: 5 | G5: 6 | H5: 7 | I5: 8 | J5: 9
A6: 1. | B6: Монтаж технологического оборудования поставки Agico Cement | F6: т | G6: =SUM(G8:G358) -> 473.08 | J6: =SUM(J8:J358) -> 0
B7: 安装AGICO供货的工艺设备
A8: 1.1 | B8: L01-IP50.IP10 | C8: Блок инертизации 1 (угольная мельница) | D8: Исполнитель | E8: Технологическое оборудование | F8: =VLOOKUP($E8,'Приложение 4'!$B$3:$C$19,2,FALSE) -> т | G8: 2.2 | I8: 0 | J8: =G8*I8 -> 0
C9: 惰性化装置1（煤磨） | D9: 施工方 | E9: 工艺设备
A10: 1.2 | B10: L01-IP50.IP20 | C10: Блок инертизации2 (200 m³ силос) | D10: Исполнитель | E10: Технологическое оборудование | F10: =VLOOKUP($E10,'Приложение 4'!$B$3:$C$19,2,FALSE) -> т | G10: 2.2 | I10: 0 | J10: =G10*I10 -> 0
C11: 惰性化装置2（200 m³料仓） | D11: 施工方 | E11: 工艺设备
A12: 1.3 | B12: L01-IP50.IP30 | C12: Блок инертизации 3 (силос 100 м3) | D12: Исполнитель | E12: Технологическое оборудование | F12: =VLOOKUP($E12,'Приложение 4'!$B$3:$C$19,2,FALSE) -> т | G12: 2.2 | I12: 0 | J12: =G12*I12 -> 0
C13: 惰性化装置3（100 m³料仓） | D13: 施工方 | E13: 工艺设备
A14: 1.4 | B14: L01-CP70 | C14: Компрессор инструментального воздуха угольного передела | D14: Исполнитель | E14: Технологическое оборудование | F14: =VLOOKUP($E14,'Приложение 4'!$B$3:$C$19,2,FALSE) -> т | G14: 0.8 | I14: 0 | J14: =G14*I14 -> 0
C15: 煤粉工段仪表空气压缩机 | D15: 施工方 | E15: 工艺设备
A16: 1.5 | B16: L11-BF07 | C16: Рукавный фильтр приемного устройства 64-5 тип | D16: Исполнитель | E16: Технологическое оборудование | F16: =VLOOKUP($E16,'Приложение 4'!$B$3:$C$19,2,FALSE) -> т | G16: 10 | I16: 0 | J16: =G16*I16 -> 0
C17: 受料装置袋收尘器 64-5型 | D17: 施工方 | E17: 工艺设备
A18: 1.6 | B18: L11-BF07.FA10 | C18: Вентилятор Рукавного фильтра приемного устройства | D18: Исполнитель | E18: Технологическое оборудование | F18: =VLOOKUP($E18,'Приложение 4'!$B$3:$C$19,2,FALSE) -> т | G18: 1.2 | I18: 0 | J18: =G18*I18 -> 0
C19: 受料装置袋收尘器风机 | D19: 施工方 | E19: 工艺设备
A20: 1.7 | B20: L11-BF07.RF10 | C20: Ячейковый питатель Рукавного фильтра приемного устройства | D20: Исполнитель | E20: Технологическое оборудование | F20: =VLOOKUP($E20,'Приложение 4'!$B$3:$C$19,2,FALSE) -> т | G20: 0.2 | I20: 0 | J20: =G20*I20 -> 0
C21: 受料装置袋收尘器分格轮给料机 | D21: 施工方 | E21: 工艺设备
A22: 1.8 | B22: L11-CP11 | C22: Компрессор инструментального воздуха приемного устройства | D22: Исполнитель | E22: Технологическое оборудование | F22: =VLOOKUP($E22,'Приложение 4'!$B$3:$C$19,2,FALSE) -> т | G22: 0.8 | I22: 0 | J22: =G22*I22 -> 0
C23: 受料装置仪表空气压缩机 | D23: 施工方 | E23: 工艺设备
A24: 1.9 | B24: L11-BM15 | C24: Устройство разгрузочное в базисный склад (передвижная тележка) | D24: Исполнитель | E24: Технологическое оборудование | F24: =VLOOKUP($E24,'Приложение 4'!$B$3:$C$19,2,FALSE) -> т | G24: 6.5 | I24: 0 | J24: =G24*I24 -> 0
C25: 基础库卸料装置（移动台车） | D25: 施工方 | E25: 工艺设备
A26: 1.10 | B26: L41-DU21.DA10 | C26: Жалюзийная заслонка регулировки горячего воздуха от холодильника ПОК №1 | D26: Исполнитель | E26: Технологическое оборудование | F26: =VLOOKUP($E26,'Приложение 4'!$B$3:$C$19,2,FALSE) -> т | G26: 0.8 | I26: 0 | J26: =G26*I26 -> 0
C27: 来自冷却机POK№1的热空气调节百叶阀 | D27: 施工方 | E27: 工艺设备
A28: 1.11 | B28: L41-DU22.DA10 | C28: Жалюзийная заслонка регулировки горячего воздуха от холодильника ПОК №1 | D28: Исполнитель | E28: Технологическое оборудование | F28: =VLOOKUP($E28,'Приложение 4'!$B$3:$C$19,2,FALSE) -> т | G28: 0.8 | I28: 0 | J28: =G28*I28 -> 0
C29: 来自冷却机POK№1的热空气调节百叶阀 | D29: 施工方 | E29: 工艺设备
A30: 1.12 | B30: L41-DA23 | C30: Направляющий аппарат бустер-вентилятора | D30: Исполнитель | E30: Технологическое оборудование | F30: =VLOOKUP($E30,'Приложение 4'!$B$3:$C$19,2,FALSE) -> т | G30: 0.8 | I30: 0 | J30: =G30*I30 -> 0
C31: 增压风机导流装置 | D31: 施工方 | E31: 工艺设备
A32: 1.13 | B32: L41-FN24 | C32: Бустер-вентилятор | D32: Исполнитель | E32: Технологическое оборудование | F32: =VLOOKUP($E32,'Приложение 4'!$B$3:$C$19,2,FALSE) -> т | G32: 3.5 | I32: 0 | J32: =G32*I32 -> 0
C33: 增压风机 | D33: 施工方 | E33: 工艺设备
A34: 1.14 | B34: L41-FN24.MT10 | C34: Электродвигатель | D34: Исполнитель | E34: Технологическое оборудование | F34: =VLOOKUP($E34,'Приложение 4'!$B$3:$C$19,2,FALSE) -> т | G34: 0 | I34: 0 | J34: =G34*I34 -> 0
C35: 电动机 | D35: 施工方 | E35: 工艺设备
A36: 1.15 | B36: L41-CN30 | C36: Циклон ПОК 1 (Заказчику предоставляется полная техническая документация для изготовления, КМД. В формате dwg.) | D36: Исполнитель | E36: Технологическое оборудование | F36: =VLOOKUP($E36,'Приложение 4'!$B$3:$C$19,2,FALSE) -> т | I36: 0 | J36: =G36*I36 -> 0
C37: POK1旋风筒 （向业主提供完整的技术制造文件，KMD。格式为dwg。） | D37: 施工方 | E37: 工艺设备
A38: 1.16 | B38: L41-CN30.RF10 | C38: Питатель ячейковый1 с двигателем | D38: Исполнитель | E38: Технологическое оборудование | F38: =VLOOKUP($E38,'Приложение 4'!$B$3:$C$19,2,FALSE) -> т | G38: 0.2 | I38: 0 | J38: =G38*I38 -> 0
C39: 分格轮给料机1（含电机） | D39: 施工方 | E39: 工艺设备
A40: 1.17 | B40: L41-CN30.MR10 | C40: Мотор-редуктор Питателя ячейковый | D40: Исполнитель | E40: Технологическое оборудование | F40: =VLOOKUP($E40,'Приложение 4'!$B$3:$C$19,2,FALSE) -> т | G40: 0 | I40: 0 | J40: =G40*I40 -> 0
...
